Workbook

Sheet Overview
A1: Field | B1: Value
A2: Project Name | B2: Data Manager AI
A3: Owner
A4: Start Date | B4: 46013
A5: Target Completion Date
A6: Reporting Cadence | B6: Weekly
A7: Last Updated | B7: 2025-12-12

Sheet Tasks
A1: Tasks ID | B1: Tasks List | C1: Tasks Category | D1: Task Map | E1: Task Discreption | F1: Assigned To | G1: Start Date | H1: Target Date | I1: Actual End Date | J1: Status | K1: % Complete | L1: Dependencies | M1: Comments
A2: Dashboard | B2: Dashboard | C2: Frontend | D2: Dashboard | F2: Arthi/Tejasree | G2: 46024 | H2: 46027 | I2: 46027 | J2: Completed
A3: Study Management | B3: Study Management | C3: Frontend | D3: Study Management | F3: Arthi/Tejasree | G3: 46024 | H3: 46027 | I3: 46027 | J3: Completed
A4: Data Integration | B4: Data Integration | C4: Frontend | D4: Data Integration | F4: Arthi/Tejasree | G4: 46027 | H4: 46029 | J4: In Progress
A5: Trail Data Management | B5: Trail Data Management | C5: Frontend | D5: Trail Data Management | F5: Arthi/Tejasree | G5: 46027 | H5: 46030 | J5: In Progress
A6: Data Manager.AI | B6: Data Manager.AI | C6: Frontend | D6: Data Manager.AI | F6: Arthi/Tejasree | G6: 46027 | H6: 46030 | J6: In Progress
A7: DB Schema - Dashboard | B7: DB Schema - Dashboard | C7: Database | D7: Dashboard | F7: Ritesh | G7: 46024 | H7: 45663 | I7: 45663 | J7: Completed
A8: DB Schema - Study Management | B8: DB Schema - Study Management | C8: Database | D8: Study Management | F8: Ritesh | G8: 46028 | H8: 46029 | J8: In Progress
A9: DB Schema - Data Integration | B9: DB Schema - Data Integration | C9: Database | D9: Data Integration | F9: Deepta | G9: 46027 | H9: 46028 | I9: 46028 | J9: Completed
A10: DB Schema - Trail Data Management | B10: DB Schema - Trail Data Management | C10: Database | D10: Trail Data Management | F10: Ritesh | G10: 46028 | H10: 46029 | J10: In Progress
A11: DB Schema - DataManager.AI | B11: DB Schema - DataManager.AI | C11: Database | D11: Data Manager.AI | F11: Hanif | G11: 46028 | H11: 46029 | J11: In Progress
A12: Populate Trail Data into PostgreSQL | B12: Populate Trail Data into PostgreSQL | C12: Database | D12: Trail Data Management | E12: Populate EDC Data(DM,SV,DS,AE...) into PostgreSQL | F12: Ruthra | G12: 46030 | H12: 46031 | J12: In Progress
A13: Study Management - CRUD - DB | B13: Study Management - CRUD - DB | C13: Backend | D13: Study Management | E13: User should be able to create new studies, sites,studycontacts, vendors, documents. | F13: Priyeshwer | J13: In Progress
A14: Creating and Integrate PostgreSQL DBs | B14: Creating and Integrate PostgreSQL DBs | C14: Backend | D14: Data Integration | F14: Priyeshwer | J14: Completed
A15: Make Refresh, Pause, Actions - Dynamic | B15: Make Refresh, Pause, Actions - Dynamic | C15: Backend | D15: Data Integration | F15: Priyeshwer | J15: Completed
A16: Scheduler | B16: Scheduler | C16: Backend | D16: Data Integration | F16: Deepta | J16: Completed
A17: Integrate Integration Logs | B17: Integrate Integration Logs | C17: Backend | D17: Data Integration | F17: Priyeshwer | J17: Not Started
A18: Build Data Quality Checks Agent | B18: Build Data Quality Checks Agent | C18: Backend | D18: Data Manager.AI | F18: Ruthra/Hanif | J18: Not Started
A19: Build Reconcilation Agent | B19: Build Reconcilation Agent | C19: Backend | D19: Data Manager.AI | F19: Ruthra/Hanif | J19: Not Started
A20: Data Fetch Agent | B20: Data Fetch Agent | C20: Backend | D20: Data Manager.AI | F20: Ruthra/Hanif | J20: Not Started
A21: DQ Processing Agent | B21: DQ Processing Agent | C21: Backend | D21: Data Manager.AI | F21: Ruthra/Hanif | J21: Not Started
A22: Protocol Check Agent | B22: Protocol Check Agent | C22: Backend | D22: Data Manager.AI | F22: Ruthra/Hanif | J22: Not Started
A23: Task Manager Agent | B23: Task Manager Agent | C23: Backend | D23: Data Manager.AI | F23: Ruthra/Hanif | J23: Not Started
A24: Test Study Management | B24: Test Study Management | C24: Backend | D24: Study Management | F24: Ritesh | J24: Not Started
A25: Test Data Integration | B25: Test Data Integration | C25: Backend | D25: Data Integration | F25: Ritesh | J25: Not Started
... A30: Monitor.ai/Notifications | B30: Monitor.ai/Notifications | C30: Backend | D30: Data Integration | F30: Deepta/Tejashree | J30: Not Started

Sheet Milestones
A1: Milestone | B1: Owner | C1: Target Date | D1: Actual Date | E1: Status | F1: Comments
A2: Front End
A3: Back End
A4: Front End
A5: Database
A6: API Integration
A7: Cloud Migration
A8: Agent Orchestration | B8: Mitul
A9: Business Rules | B9: Prabhakar | E9: Not Started | F9: discuss for better Rules engine
A10: Cloud CI-CD Set-up
A11: Creating separeate Azure cluster | B11: Mitul
A12: Send Team email ID | B12: Eswar | C12: done
A13: Access to Azure Portal | B13: STG Team
A14: Subscriton ID | B14: Mitul
A15: Connect with STG team with SubscriotionID | B15: Eswar & Mitul | C15: not done
A16: Contributor Access to Eswar and Prabhakar | B16: Mitul | C16: not done
A17: Contributor access role Training to ESWAr and Prabhakar | B17: Mitul
A18: Azure Pipeline creation | B18: Mitul
A19: Git Repo switch to Azure Repo | B19: Mitul
A20: .ENV files to Mitul | B20: Eswar | C20: not done
A22: Meet with Venkata and Team
A23: Rule Engine

Sheet Risks_Issues
A1: ID | B1: Risk / Issue | C1: Type (Risk/Issue) | D1: Impact | E1: Likelihood | F1: Severity (=Impact x Likelihood) | G1: Mitigation / Action | H1: Owner | I1: Target Date | J1: Status
B2: Azure license | F2: =IF(D2="", "", (IF(D2="Low",1,IF(D2="Medium",2,IF(D2="High",3,0)))) * (IF(E2="Low",1,IF(E2="Medium",2,IF(E2="High",3,0)))))
B3: Resource Group needs to be created | F3: =IF(D3="", "", (IF(D3="Low",1,IF(D3="Medium",2,IF(D3="High",3,0)))) * (IF(E3="Low",1,IF(E3="Medium",2,IF(E3="High",3,0)))))
B4: Postgress | F4: =IF(D4="", "", (IF(D4="Low",1,IF(D4="Medium",2,IF(D4="High",3,0)))) * (IF(E4="Low",1,IF(E4="Medium",2,IF(E4="High",3,0)))))
B5: Python fast API | F5: =IF(D5="", "", (IF(D5="Low",1,IF(D5="Medium",2,IF(D5="High",3,0)))) * (IF(E5="Low",1,IF(E5="Medium",2,IF(E5="High",3,0)))))
B6: Gemini 2.5 Flash /dummy data | F6: =IF(D6="", "", (IF(D6="Low",1,IF(D6="Medium",2,IF(D6="High",3,0)))) * (IF(E6="Low",1,IF(E6="Medium",2,IF(E6="High",3,0)))))
B7: Azure Data Foundry - Production/POC | F7: =IF(D7="", "", (IF(D7="Low",1,IF(D7="Medium",2,IF(D7="High",3,0)))) * (IF(E7="Low",1,IF(E7="Medium",2,IF(E7="High",3,0)))))
B8: Multi-LLMS/Multi-Agents ? | F8: =IF(D8="", "", (IF(D8="Low",1,IF(D8="Medium",2,IF(D8="High",3,0)))) * (IF(E8="Low",1,IF(E8="Medium",2,IF(E8="High",3,0)))))
F9: =IF(D9="", "", (IF(D9="Low",1,IF(D9="Medium",2,IF(D9="High",3,0)))) * (IF(E9="Low",1,IF(E9="Medium",2,IF(E9="High",3,0)))))
F10: =IF(D10="", "", (IF(D10="Low",1,IF(D10="Medium",2,IF(D10="High",3,0)))) * (IF(E10="Low",1,IF(E10="Medium",2,IF(E10="High",3,0)))))
A11: Notes | F11: =IF(D11="", "", (IF(D11="Low",1,IF(D11="Medium",2,IF(D11="High",3,0)))) * (IF(E11="Low",1,IF(E11="Medium",2,IF(E11="High",3,0)))))
B12: Azure Access | F12: =IF(D12="", "", (IF(D12="Low",1,IF(D12="Medium",2,IF(D12="High",3,0)))) * (IF(E12="Low",1,IF(E12="Medium",2,IF(E12="High",3,0)))))
B13: Azure PostgreSQL DB | C13: Risk | F13: =IF(D13="", "", (IF(D13="Low",1,IF(D13="Medium",2,IF(D13="High",3,0)))) * (IF(E13="Low",1,IF(E13="Medium",2,IF(E13="High",3,0)))))
B14: Azure Blob Storage | C14: Risk | F14: =IF(D14="", "", (IF(D14="Low",1,IF(D14="Medium",2,IF(D14="High",3,0)))) * (IF(E14="Low",1,IF(E14="Medium",2,IF(E14="High",3,0)))))
B15: Azure Key Vault | C15: Risk | F15: =IF(D15="", "", (IF(D15="Low",1,IF(D15="Medium",2,IF(D15="High",3,0)))) * (IF(E15="Low",1,IF(E15="Medium",2,IF(E15="High",3,0)))))
B16: Azure App Services | C16: Risk | F16: =IF(D16="", "", (IF(D16="Low",1,IF(D16="Medium",2,IF(D16="High",3,0)))) * (IF(E16="Low",1,IF(E16="Medium",2,IF(E16="High",3,0)))))
B17: Azure Monitor | C17: Risk
B18: Azure Logic Apps | C18: Risk | F18: =IF(D18="", "", (IF(D18="Low",1,IF(D18="Medium",2,IF(D18="High",3,0)))) * (IF(E18="Low",1,IF(E18="Medium",2,IF(E18="High",3,0)))))
B19: Application Insights | F19: =IF(D19="", "", (IF(D19="Low",1,IF(D19="Medium",2,IF(D19="High",3,0)))) * (IF(E19="Low",1,IF(E19="Medium",2,IF(E19="High",3,0)))))
A20: Open -AI and Orchestration | B20: Azure Foundry | F20: =IF(D20="", "", (IF(D20="Low",1,IF(D20="Medium",2,IF(D20="High",3,0)))) * (IF(E20="Low",1,IF(E20="Medium",2,IF(E20="High",3,0)))))
A21: RAG | B21: Azure-AI Search | F21: =IF(D21="", "", (IF(D21="Low",1,IF(D21="Medium",2,IF(D21="High",3,0)))) * (IF(E21="Low",1,IF(E21="Medium",2,IF(E21="High",3,0)))))
B22: RADIS Cache
A23: User Management | B23: Entra ID / Hexaware SSO/Client SSO
B24: API Subnet
A25: Agent Orchestration | B25: Symeantic Kernel
B26: Azure documents
F27: =IF(D27="", "", (IF(D27="Low",1,IF(D27="Medium",2,IF(D27="High",3,0)))) * (IF(E27="Low",1,IF(E27="Medium",2,IF(E27="High",3,0)))))
A29: Front END | B29: React | F29: =IF(D29="", "", (IF(D29="Low",1,IF(D29="Medium",2,IF(D29="High",3,0)))) * (IF(E29="Low",1,IF(E29="Medium",2,IF(E29="High",3,0)))))
A30: AI | B30: FAST API | F30: =IF(D30="", "", (IF(D30="Low",1,IF(D30="Medium",2,IF(D30="High",3,0)))) * (IF(E30="Low",1,IF(E30="Medium",2,IF(E30="High",3,0)))))
A31: Database | B31: Postgress | F31: =IF(D31="", "", (IF(D31="Low",1,IF(D31="Medium",2,IF(D31="High",3,0)))) * (IF(E31="Low",1,IF(E31="Medium",2,IF(E31="High",3,0)))))
F32: =IF(D32="", "", (IF(D32="Low",1,IF(D32="Medium",2,IF(D32="High",3,0)))) * (IF(E32="Low",1,IF(E32="Medium",2,IF(E32="High",3,0)))))
F33: =IF(D33="", "", (IF(D33="Low",1,IF(D33="Medium",2,IF(D33="High",3,0)))) * (IF(E33="Low",1,IF(E33="Medium",2,IF(E33="High",3,0)))))
F34: =IF(D34="", "", (IF(D34="Low",1,IF(D34="Medium",2,IF(D34="High",3,0)))) * (IF(E34="Low",1,IF(E34="Medium",2,IF(E34="High",3,0)))))
F35: =IF(D35="", "", (IF(D35="Low",1,IF(D35="Medium",2,IF(D35="High",3,0)))) * (IF(E35="Low",1,IF(E35="Medium",2,IF(E35="High",3,0)))))
F36: =IF(D36="", "", (IF(D36="Low",1,IF(D36="Medium",2,IF(D36="High",3,0)))) * (IF(E36="Low",1,IF(E36="Medium",2,IF(E36="High",3,0)))))
F37: =IF(D37="", "", (IF(D37="Low",1,IF(D37="Medium",2,IF(D37="High",3,0)))) * (IF(E37="Low",1,IF(E37="Medium",2,IF(E37="High",3,0)))))
F38: =IF(D38="", "", (IF(D38="Low",1,IF(D38="Medium",2,IF(D38="High",3,0)))) * (IF(E38="Low",1,IF(E38="Medium",2,IF(E38="High",3,0)))))
F39: =IF(D39="", "", (IF(D39="Low",1,IF(D39="Medium",2,IF(D39="High",3,0)))) * (IF(E39="Low",1,IF(E39="Medium",2,IF(E39="High",3,0)))))
F40: =IF(D40="", "", (IF(D40="Low",1,IF(D40="Medium",2,IF(D40="High",3,0)))) * (IF(E40="Low",1,IF(E40="Medium",2,IF(E40="High",3,0)))))
F41: =IF(D41="", "", (IF(D41="Low",1,IF(D41="Medium",2,IF(D41="High",3,0)))) * (IF(E41="Low",1,IF(E41="Medium",2,IF(E41="High",3,0)))))
...

Sheet Metrics
A1: Metric | B1: =COUNTA(Tasks!A2:A500)
A2: Total Tasks | B2: =COUNTIFS(Tasks!J2:J500,"Completed")
A3: Completed Tasks | B3: =COUNTIFS(Tasks!J2:J500,"In Progress")
A4: In Progress Tasks | B4: =COUNTIFS(Tasks!J2:J500,"Not Started")
A5: Not Started Tasks | B5: =COUNTIFS(Tasks!J2:J500,"On Hold")
A6: On Hold Tasks | B6: =COUNTIFS(Tasks!J2:J500,"<>Completed",Tasks!H2:H500,"<"&TODAY())
A7: Overdue Tasks | B7: =IF(B1=0,0,SUM(Tasks!K2:K500)/B1/100)
A8: % Completion (Weighted by % Complete) | B8: =IFERROR(SUMPRODUCT(#REF!, --(#REF!<>"")) / COUNTIF(#REF!,">=0"), 0)

Sheet Team Work Challenges
A1: Date | B1: Task | C1: Task Details | D1: Who | E1: Resolved (Yes/No) | F1: Resolved By?

Sheet Sheet1
A1: Date | B1: Task | C1: status
A2: 46027 | B2: Update Target dates
B3: start business rules
B4: Update Task Map- Datamanager,Central Monitor
B5: Effort Tracker
B6: Daily Task Tracker-
B7: Update Task Start date

Sheet Sheet3
A2: Count of Status | B2: Status
A3: Tasks Category | B3: Completed | C3: In Progress | D3: Not Started | E3: (blank) | F3: Grand Total
A4: Backend | C4: 1 | D4: 17 | F4: 18
A5: Database | B5: 2 | C5: 4 | F5: 6
A6: Frontend | B6: 2 | C6: 3 | F6: 5
A7: (blank)
A8: Grand Total | B8: 4 | C8: 8 | D8: 17 | F8: 29

Sheet Sheet7
A1: Tasks Category | B1: Completed | C1: In Progress | D1: Not Started
A2: Backend | C2: 1 | D2: 17
A3: Database | B3: 2 | C3: 4
A4: Frontend | B4: 2 | C4: 3

Sheet Sheet4
A2: Assigned To | B2: Count of Assigned To
A3: Ritesh | B3: 8
A4: Ruthra/Hanif | B4: 6
A5: Arthi/Tejasree | B5: 5
A6: Priyeshwer | B6: 4
A7: Deepta | B7: 2
A8: Ruthra | B8: 1
A9: Aarthi | B9: 1
A10: Deepta/Tejashree | B10: 1
A11: Hanif | B11: 1
A12: Grand Total | B12: 29

Sheet Sheet5
A2: Count of Assigned To | B2: Status
A3: Assigned To | B3: Not Started | C3: In Progress | D3: Completed | E3: Grand Total
A4: Ritesh | B4: 5 | C4: 2 | D4: 1 | E4: 8
A5: Ruthra/Hanif | B5: 6 | E5: 6
A6: Arthi/Tejasree | C6: 3 | D6: 2 | E6: 5
A7: Priyeshwer | B7: 3 | C7: 1 | E7: 4
A8: Deepta | B8: 1 | D8: 1 | E8: 2
A9: Ruthra | C9: 1 | E9: 1
A10: Aarthi | B10: 1 | E10: 1
A11: Deepta/Tejashree | B11: 1 | E11: 1
A12: Hanif | C12: 1 | E12: 1
A13: Grand Total | B13: 17 | C13: 8 | D13: 4 | E13: 29

Sheet Sheet6
A2: Count of Tasks Category | C2: Status
A3: Tasks Category | B3: Assigned To | C3: Not Started | D3: In Progress | E3: Completed | F3: Grand Total
A4: Backend | B4: Ruthra/Hanif | C4: 6 | F4: 6
B5: Ritesh | C5: 5 | F5: 5
B6: Priyeshwer | C6: 3 | D6: 1 | F6: 4
B7: Deepta | C7: 1 | F7: 1
B8: Aarthi | C8: 1 | F8: 1
B9: Deepta/Tejashree | C9: 1 | F9: 1
A10: Backend Total | C10: 17 | D10: 1 | F10: 18
A11: Database | B11: Ritesh | D11: 2 | E11: 1 | F11: 3
B12: Ruthra | D12: 1 | F12: 1
B13: Deepta | E13: 1 | F13: 1
B14: Hanif | D14: 1 | F14: 1
A15: Database Total | D15: 4 | E15: 2 | F15: 6
A16: Frontend | B16: Arthi/Tejasree | D16: 3 | E16: 2 | F16: 5
A17: Frontend Total | D17: 3 | E17: 2 | F17: 5
A18: Grand Total | C18: 17 | D18: 8 | E18: 4 | F18: 29
